#VRML_SIM R2023b utf8

EXTERNPROTO "https://raw.githubusercontent.com/cyberbotics/webots/R2023b/projects/objects/backgrounds/protos/TexturedBackground.proto"
EXTERNPROTO "https://raw.githubusercontent.com/cyberbotics/webots/R2023b/projects/objects/backgrounds/protos/TexturedBackgroundLight.proto"

WorldInfo {
}
Viewpoint {
  orientation -0.6263417204457135 0.5694193367742496 0.5324074268233657 2.14586199762895
  position -0.3833151542348541 0.6650944478951514 3.5410268802467693
}
TexturedBackground {
}
TexturedBackgroundLight {
}
Robot {
  children [
    Solid {
      children [
        CadShape {
          url [
            "../cad/split_parts/part_4.obj"
          ]
        }
      ]
      name "BASE"
      boundingObject Mesh {
        url [
          "../cad/split_parts/part_4.obj"
        ]
      }
      physics Physics {
      }
    }
    DEF joint1 HingeJoint {
      jointParameters HingeJointParameters {
        axis 0 0 1
        anchor -0.35 0.15 0
      }
      device [
        RotationalMotor {
          name "motor1"
        }
      ]
      endPoint DEF press Solid {
        children [
          CadShape {
            url [
              "../cad/split_parts/part_2.obj"
            ]
          }
          DEF joint2 HingeJoint {
            jointParameters HingeJointParameters {
              axis 0 0 1
              anchor -0.054 0.101 0
            }
            endPoint Solid {
              children [
                CadShape {
                  url [
                    "../cad/split_parts/part_3.obj"
                  ]
                }
                DEF joint3 HingeJoint {
                  jointParameters HingeJointParameters {
                    axis 0 0 1
                    anchor -0.08 0.5002 0
                  }
                  endPoint Solid {
                    children [
                      CadShape {
                        url [
                          "../cad/split_parts/part_1.obj"
                        ]
                      }
                      DEF joint4 HingeJoint {
                        jointParameters HingeJointParameters {
                          axis 0 0 1
                          anchor 0.1 0.5 0
                        }
                        endPoint SolidReference {
                          solidName "<static environment>"
                        }
                      }
                    ]
                    name "shooter"
                    boundingObject Mesh {
                      url [
                        "../cad/split_parts/part_1.obj"
                      ]
                    }
                    physics Physics {
                    }
                  }
                }
              ]
              name "connector"
              boundingObject Mesh {
                url [
                  "../cad/split_parts/part_3.obj"
                ]
              }
              physics Physics {
              }
            }
          }
        ]
        boundingObject Mesh {
          url [
            "../cad/split_parts/part_2.obj"
          ]
        }
        physics Physics {
        }
      }
    }
  ]
  controller "w14_controller"
}
