#VRML_SIM R2023b utf8

EXTERNPROTO "../protos/TexturedBackground.proto"
EXTERNPROTO "../protos/TexturedBackgroundLight.proto"

WorldInfo {
  info [
    "fourbar linkage"
  ]
}
Viewpoint {
  orientation -0.17524366601960317 0.20799757991102616 0.9623027924053665 1.7913508311753839
  position 1.0571588458938594 -2.502126861220829 1.490364369030099
}
TexturedBackground {
}
TexturedBackgroundLight {
}
DEF FOURBAR Robot {
  children [
    DEF BASE Solid {
      children [
        CadShape {
          url [
            "../split_parts/base.obj"
          ]
        }
      ]
      name "BASE"
    }
    DEF JOINT1 HingeJoint {
      jointParameters HingeJointParameters {
        axis 0 0 1
      }
      device [
        RotationalMotor {
          name "joint_motor1"
        }
      ]
      endPoint DEF LINK1 Solid {
        children [
          CadShape {
            url [
              "../split_parts/link1.obj"
            ]
          }
        ]
        name "LINK1"
      }
    }
  ]
  controller "fourbar_controller1"
}
