#VRML_SIM R2023b utf8

EXTERNPROTO "../protos/TexturedBackground.proto"
EXTERNPROTO "../protos/TexturedBackgroundLight.proto"

WorldInfo {
  info [
    "fourbar linkage"
  ]
}
Viewpoint {
  orientation -0.17524366601960317 0.20799757991102616 0.9623027924053665 1.7913508311753839
  position 1.0571588458938594 -2.502126861220829 1.490364369030099
}
TexturedBackground {
}
TexturedBackgroundLight {
}
DEF FOURBAR Robot {
  children [
    DEF BASE Solid {
      children [
        CadShape {
          url [
            "../split_parts/base.obj"
          ]
        }
      ]
      name "BASE"
    }
    DEF JOINT1 HingeJoint {
      jointParameters HingeJointParameters {
        axis 0 0 1
        anchor 0 0 0 
      }
      device [
        RotationalMotor {
          name "joint_motor1"
        }
      ]
      endPoint DEF LINK1 Solid {
        children [
          CadShape {
            url [
              "../split_parts/link1.obj"
            ]
          }
          DEF JOINT2 HingeJoint {
            jointParameters HingeJointParameters {
              axis 0 0 1
              anchor 0 0.4 0
            }
            device [
              RotationalMotor {
                name "joint_motor2"
              }
            ]
            endPoint DEF LINK2 Solid {
                children [
                  CadShape {
                    url [
                      "../split_parts/link2.obj"
                    ]
                  }
                  DEF JOINT3 HingeJoint{
                    jointParameters HingeJointParameters {
                      axis 0 0 1
                      anchor 0.5425 0.6563 0
                    }
                    device [
                      RotationalMotor {
                        name "joint_motor3"
                      }
                    ]
                    endPoint DEF LINK3 Solid {
                        children [
                          CadShape {
                            url [
                              "../split_parts/link3.obj"
                            ]
                          }
                        ]
                      name "LINK3"
                    }
                  }
                ]
              name "LINK2"
            }
          }
        ]
        name "LINK1"
      }
    }
  ]
  controller "fourbar_controller3"
}
